Workbook

Sheet NEW PRODUCTION
A2: Tank size (gallons) | B2: 1200 | E2: Tank size (gallons) | F2: 2000 | I2: Tank size (gallons) | J2: 3000
A3: Ounces | B3: =B2*128 -> 153600 | E3: Ounces | F3: =F2*128 -> 256000 | I3: Ounces | J3: =J2*128 -> 384000
A4: 12oz units | B4: =B3/12 -> 12800 | E4: 12oz units | F4: =F3/12 -> 21333.333 | I4: 12oz units | J4: =J3/12 -> 32000
A5: Cases | B5: =B4/24 -> 533.33333 | E5: Cases | F5: =F4/24 -> 888.88889 | I5: Cases | J5: =J4/24 -> 1333.3333
A6: Yeild | B6: 0.93 | E6: Yeild | F6: 0.93 | I6: Yeild | J6: 0.93
A7: Post Yield CS | B7: =B5*B6 -> 496 | E7: Post | F7: =F5*F6 -> 826.66667 | I7: Post | J7: =J5*J6 -> 1240
A8: Pallets | B8: =B5/91 -> 5.8608059 | E8: Pallets | F8: =F7/91 -> 9.0842491 | I8: Pallets | J8: =J7/91 -> 13.626374
E10: *run Orange and Rootbeer in October?
F13: 15 pallets and below should go on an LTL
A15: *how many pallets per truck? 22 FTL
B19: Erythritol cost | C19: 250.65 | D19: 55lb

Sheet Paktech Pricing 2025
A2: 2025 PRICE SHEET
C3: HANDLE | D3: QPCE-202-227-PCR | F3: EFFECTIVE DATES | G3: 1/1/2025 - 12/31/2025
C5: PALLETS | D5: PRICE PER 1000 PARTS | F5: PACKAGING | H5: Price | I5: Unit | J5: Price per unit | K5: Units per Case | L5: Cost per Case | M5: Cost per pallet | O5: Soda Cases per Paktech pallet | P5: Pallets of Soda
C6: 26-30 | D6: 102.9 | F6: HANDLES PER PALLET | G6: 36160 | H6: =D12 -> 137.1 | I6: 1000 | J6: =H6/I6 -> 0.1371 | K6: 8 | L6: =K6*J6 -> 1.0968 | M6: =G6/1000*H6 -> 4957.536 | O6: =G6/8 -> 4520 | P6: =O6/90 -> 50.222222 | Q6: =O6*L13 -> 5858.416
C7: 14-25 | D7: 104.6 | F7: HANDLES PER BOX | G7: 904 | K7: shipping | L7: =250/O6 -> 0.055309735
C8: 5-13 | D8: 107.5 | F8: BOXES PER PALLET | G8: 40 | K8: Total | L8: =SUM(L6:L7) -> 1.1521097
C9: 4 | D9: 110.8
C10: 3 | D10: 117.1 | F10: LABEL
C11: 2 | D11: 125.5 | F11: UPC LABEL PRICING | G11: $18/1000 parts | H11: 18 | I11: 1000 | J11: =H11/I11 -> 0.018 | K11: 8 | L11: =K11*J11 -> 0.144 | N11: wouldn't know mix | P11: =O11/90 -> 0
C12: 1 | D12: 137.1 | F12: DECO LABEL PRICING | G12: $25/1000 parts | H12: 25 | I12: 1000 | J12: =H12/I12 -> 0.025 | K12: 8 | N12: don't need deco label
A13: THE PAKTECH DIFFERENCE: • What makes PakTech handles the preferred packaging choice? Easy: PakTech handles are Smart, Sustainable, Simple, and made in the USA. | K13: Total with UPC | L13: =L12+L11+L8 -> 1.2961097 | P13: \
B14: SMART: Our 100% recycled HDPE handles are strong, flexible, durable, and easy to apply. The smart way to protect your product. SUSTAINABLE: Made from 100% recycled HDPE and indefinitely recyclable. Our handles are the clear sustainable choice. | F14: SIMPLE: Designed with the user in mind, PakTech handles are safe, secure, and user friendly. Highlight your brand with our minimal packaging handles. MADE IN USA: Made proudly in Eugene, Oregon USA
A15: COLORS: • Various colors offered. 31 standard colors plus custom color match. Value-added shelf appeal: Make your brand pop with our wide array of colors.
A16: PLEASE NOTE: • All pricing is in US Dollars, FOB Eugene, Oregon and is quoted by the thousand handles (M) • Pricing subject to applicable surcharge effective at the time of order • Minimum order quantity is 1 pallet. Any orders less than 25,000 parts or 1 pallet (whichever is less) are $0.35/ea. and must be ordered in full box quantities | E16: • One-time start-up fee of $500 per each new UPC code or Deco label • One color per pallet standard. Up to two colors per pallet with an additional fee of $400/pallet • This pricing supersedes any previous pricing & is subject to change due to unforeseen circumstances • All sales are subject to our Terms and Conditions available at www.paktech-opi.com/terms
A17: www.paktech-opi.com | Phone: 541.461.5000 | Fax: 541.461.5005 | Eugene, OR 97402 | Social: @PakTech

Sheet Quantum Run 02-23-26 line items
C16: diet cola | D16: 408
C17: lemon lime | D17: 432
C18: ginger beer | D18: 423
C19: cola | D19: 602
C20: Total Cases | D20: =SUM(D16:D19) -> 1865 | E20: =I21/D20 -> 0
C22: Current Balance | D22: 57828.66
C23: Add back credit (that we haven't realized) | D23: 5997.6
C24: Add TFC | D24: 2195
C25: Subtract down payment for March | D25: -20460
D26: =SUM(D22:D25) -> 45561.26
D28: =D26/D20 -> 24.42963

Sheet Quantum Run 11-06-25 line items
A1: Transaction date | B1: Transaction type | C1: Num | D1: Name | E1: Memo/Description | F1: Full name | G1: Item split account | H1: Amount | I1: Balance
A2: 06/14/2025 | B2: Journal Entry | C2: 1577 | F2: Can Raw Materials | H2: -202779.67 | I2: 13081.88 | J2: this is the value of 14179lbs of the leftover sugar
D3: 1700 lbs of Sugar to be charged to Shane Top Hat | I3: =(1700/(8133+4346+1700))*I2*-1 -> -1568.4601 | J3: NEED TO JE
I4: =SUM(I2:I3) -> 11513.42
A5: 06/15/2025 | B5: Journal Entry | C5: 1578 | E5: credit for first run rate adjustment - see Sky's note to Calli in Trello | F5: Can Raw Materials | H5: -5997.6 | I5: 13081.88 | J5: 5597 is a credit that we might realize from the previous run. Need to figure out credit from this run.
D6: 4346lbs of Sugar used in November 2025 Alameda run | H6: =(4346/(8133+4346+1700))*I2 -> 4009.7222 | J6: NEED TO JE
A7: 08/26/2025 | B7: Vendor Credit | D7: ORTHODOX UNION | E7: account | F7: Can Raw Materials | G7: Accounts Payable (A/P) | H7: -950 | I7: 12131.88
A8: 09/03/2025 | B8: Bill | C8: BB004 | D8: Craft Beverage Packaging Solutions | E8: Total | F8: Can Raw Materials | G8: Accounts Payable (A/P) | H8: 1785 | I8: 13916.88
A9: 09/26/2025 | B9: Bill | C9: 1538 | D9: Quantum Canning | F9: Can Raw Materials | G9: Accounts Payable (A/P) | H9: 27900 | I9: 41816.88
A10: 09/26/2025 | B10: Bill | C10: 1583 | D10: Quantum Canning | F10: Can Raw Materials | G10: Accounts Payable (A/P) | H10: 13950 | I10: 55766.88
A11: 10/07/2025 | B11: Bill | C11: BB-005 | D11: Craft Beverage Packaging Solutions | E11: Total | F11: Can Raw Materials | G11: Accounts Payable (A/P) | H11: 2600.01 | I11: 58366.89
A12: 10/24/2025 | B12: Bill | C12: 2,407.71 | D12: Craft Beverage Packaging Solutions | F12: Can Raw Materials | G12: Accounts Payable (A/P) | H12: 2407.71 | I12: 60774.6
A13: 10/24/2025 | B13: Bill | C13: 27001 | D13: AC CALDERONI* | E13: flavor | F13: Can Raw Materials | G13: Accounts Payable (A/P) | H13: 1098.16 | I13: 61872.76
A14: 11/03/2025 | B14: Bill | D14: AC CALDERONI* | E14: canning fees | F14: Can Raw Materials | G14: Accounts Payable (A/P) | H14: 1200 | I14: 64915.96
A15: 11/05/2025 | B15: Bill | C15: 125812521 | D15: TFC LLC | E15: Total | F15: Can Raw Materials | G15: Accounts Payable (A/P) | H15: 1925 | I15: 66840.96
A16: 11/06/2025 | B16: Bill | C16: 1618 | D16: Quantum Canning | F16: Can Raw Materials | G16: Accounts Payable (A/P) | H16: 9389.72 | I16: 76230.68
A17: 11/06/2025 | B17: Bill | C17: BB-007 | D17: Craft Beverage Packaging Solutions | F17: Can Raw Materials | G17: Accounts Payable (A/P) | H17: 2257.5 | I17: 78488.18
A18: 11/01/2025 | B18: Expense | C18: 226 | E18: Receipt for coffee and croissant purchase at Farley's in Oakland Airport | F18: Can Raw Materials | G18: NEW Capital One Business Card | H18: 15.3 | I18: =I17+H18 -> 78503.48
A19: 11/03/2025 | B19: Expense | D19: Enterprise Rent-A-Car | E19: ENTERPRISE RENT-A-CAR - 8703 Denver production | F19: Can Raw Materials | G19: NEW Capital One Business Card | H19: 68.29 | I19: =I18+H19 -> 78571.77
A20: 11/03/2025 | B20: Expense | E20: OAK SHOP THE TOWN - 8703 Denver Run | F20: Can Raw Materials | G20: NEW Capital One Business Card | H20: 5.04 | I20: =I19+H20 -> 78576.81
A21: 11/03/2025 | B21: Expense | E21: OAK SHOP THE TOWN - 8703 | F21: Can Raw Materials | G21: NEW Capital One Business Card | H21: 3.99 | I21: =I20+H21 -> 78580.8
A22: 11/03/2025 | B22: Expense | E22: DEN SMASH BURGER C #68 - 8703 Denver canning run | F22: Can Raw Materials | G22: NEW Capital One Business Card | H22: 23.95 | I22: =I21+H22 -> 78604.75
A23: 11/01/2025 | B23: Expense | D23: Southwest | H23: 996 | I23: =I22+H23 -> 79600.75
H24: =SUM(H6:H23) -> 68685.392 | I24: =I23 -> 79600.75
I25: =H5*-1 -> 5997.6 | J25: 5597 is a credit that we might realize from the previous run. Need to figure out credit from this run.
H27: -20925 | I27: *This is the down payment applied to the next run
H28: =H24+H27 -> 47760.392
K33: Nov 2025 | L33: Apr 2025 | M33: Dif
I34: Cases | K34: =K60 -> 1902 | L34: ='Quantum Run 04042025 line items'!H61 -> 9712
I35: Quantum Canning | J35: =(H9+H10+H16)+H27 -> 30314.72 | K35: =J35/$K$60 -> 15.938339 | L35: 15.946909 | M35: =K35-L35 -> -0.0085703876
I36: Calli - Craft Beverage Packaging Solutions | J36: =H17+H12+H11+H8 -> 9050.22 | K36: =J36/$K$60 -> 4.758265 | L36: 0.84766989 | M36: =K36-L36 -> 3.9105951
I37: Orthodox Union | J37: =H7 -> -950 | K37: =J37/$K$60 -> -0.49947424 | L37: 0.097817133 | M37: =K37-L37 -> -0.59729137 | P37: Total Gallons | Q37: 4500
I38: Shipping | J38: =H15 -> 1925 | K38: =J38/$K$60 -> 1.0120925 | L38: 1.157846 | M38: =K38-L38 -> -0.14575343 | P38: Raw Syrup | Q38: =Q37/6 -> 750
I39: AC Calderoni Ingredients | J39: =H13+H6 -> 5107.8822 | K39: =J39/$K$60 -> 2.6855322 | L39: 2.1745161 | M39: =K39-L39 -> 0.51101609 | P39: Canning Fee | Q39: 1.6
I40: AC Cald Canning Fees | J40: =H14 -> 1200 | K40: =J40/$K$60 -> 0.63091483 | L40: 0.59376236 | M40: =K40-L40 -> 0.037152471 | P40: Total Fee | Q40: =Q38*Q39 -> 1200
I41: Travel | J41: =SUM(H18:H23) -> 1112.57 | K41: =J41/$K$60 -> 0.58494742 | L41: 0.060770181 | M41: =K41-L41 -> 0.52417724
K42: =SUM(K35:K41) -> 25.110616 | L42: =SUM(L35:L41) -> 20.879291 | M42: =K42-L42 -> 4.2313257
K45: Nov 2025 | L45: Future | M45: Dif
I46: Cases | K46: 1902
I47: Quantum Canning | J47: 30314.72 | K47: 15.938339 | L47: 15.946909 | M47: =L47-K47 -> 0.0085703876
...

Sheet Quantum Run 04042025 line items
I3: =251988 -> 251988 | K3: =I3/24 -> 10499.5
K4: =H38/K3 -> 0.92499643
A5: Transaction date | B5: Transaction type | C5: Num | D5: Name | E5: Memo/Description | F5: Full name | G5: Item split account | H5: Amount | I5: Balance
A6: 01/30/2025 | B6: Journal Entry | C6: 1560 | F6: Can Raw Materials | H6: -20699.27
A7: 01/31/2025 | B7: Bill | D7: Craft Beverage Packaging Solutions | F7: Can Raw Materials | G7: Accounts Payable (A/P) | H7: 472.5 | I7: 472.5
A8: 01/31/2025 | B8: Bill | D8: Craft Beverage Packaging Solutions | E8: Total | F8: Can Raw Materials | G8: Accounts Payable (A/P) | H8: 262.5 | I8: 735
A9: 02/02/2025 | B9: Bill | C9: 573125 | D9: ORTHODOX UNION | E9: Kosher Cost For Quantum | F9: Can Raw Materials | G9: Accounts Payable (A/P) | H9: 950 | I9: 1685
A10: 04/04/2025 | B10: Bill | C10: 1415 | D10: Quantum Canning | E10: Deposit - 202,000 units @ $0.31 | F10: Can Raw Materials | G10: Accounts Payable (A/P) | H10: 62620 | I10: 64305
A11: 04/04/2025 | B11: Expense | D11: Craft Beverage Packaging Solutions | F11: Can Raw Materials | G11: Chase Business Checking | H11: 4226.25 | I11: 68531.25
A12: 04/21/2025 | B12: Bill | C12: 1430 | D12: Quantum Canning | E12: Deposit - adjusted to 251,988 units @ $ 0.37 | F12: Can Raw Materials | G12: Accounts Payable (A/P) | H12: 62114.06 | I12: 130645.31
A13: 05/30/2025 | B13: Bill | C13: 1462 | D13: Quantum Canning | F13: Can Raw Materials | G13: Accounts Payable (A/P) | H13: 40142.32 | I13: 221295.23
A14: 06/11/2025 | B14: Vendor Credit | C14: CREDIT FOR OVERPAYMEN | D14: Quantum Canning | E14: Credit for overpayment to be wired - see 06/04 emails from JT and Callie | F14: Can Raw Materials | G14: Accounts Payable (A/P) | H14: -10000 | I14: 215861.55 | K14: included in 04042025 run
A15: 04/24/2025 | B15: Expense | F15: Can Raw Materials | G15: American Express | H15: 590.2 | I15: 131235.51
A16: 04/25/2025 | B16: Bill | C16: 2668 | D16: AC CALDERONI* | F16: Can Raw Materials | G16: Accounts Payable (A/P) | H16: 30579.36 | I16: 161814.87
A17: 04/28/2025 | B17: Vendor Credit | D17: AC CALDERONI* | E17: diet cola sweetener that had to be dumped 40 04/28/2025 | F17: Can Raw Materials | G17: Accounts Payable (A/P) | I17: 161814.87
A18: 04/28/2025 | B18: Vendor Credit | D18: AC CALDERONI* | E18: diet cola flavor the had to be dumped 10 04/28/2025 | F18: Can Raw Materials | G18: Accounts Payable (A/P) | I18: 161814.87
A19: 04/29/2025 | B19: Bill | C19: 123013922 | D19: TFC LLC | E19: 22 pallets | F19: Can Raw Materials | G19: Accounts Payable (A/P) | H19: 1975 | I19: 163789.87 | K19: =0.61*888*24 -> 13000.32
A20: 05/01/2025 | B20: Bill | C20: 26768 | D20: AC CALDERONI* | E20: canning fees | F20: Can Raw Materials | G20: Accounts Payable (A/P) | H20: 5766.62 | I20: 169556.49
A21: 05/07/2025 | B21: Bill | C21: 123106464 | D21: TFC LLC | E21: 22 pallets | F21: Can Raw Materials | G21: Accounts Payable (A/P) | H21: 1975 | I21: 171531.49
A22: 05/13/2025 | B22: Bill | C22: 26731 | D22: AC CALDERONI* | E22: Freight | F22: Can Raw Materials | G22: Accounts Payable (A/P) | H22: 3200 | I22: 174731.49
A23: 05/13/2025 | B23: Bill | C23: 26731 | D23: AC CALDERONI* | E23: Brix Diet Hangar 25 Cola TOTE 760x$4.25 | F23: Can Raw Materials | G23: Accounts Payable (A/P) | H23: 3230 | I23: 177961.49
A24: 05/13/2025 | B24: Bill | C24: 26731 | D24: AC CALDERONI* | E24: Freight credit for diet cola mistake | F24: Can Raw Materials | G24: Accounts Payable (A/P) | H24: -3200 | I24: 174761.49
A25: 05/14/2025 | B25: Bill | C25: Q26732 | D25: AC CALDERONI* | E25: ONE GALLON NATURAL SYRUP GOLDEN GATE ORANGE FOR CANS | F25: Can Raw Materials | G25: Accounts Payable (A/P) | H25: 32.32 | I25: 174793.81
A26: 05/14/2025 | B26: Bill | C26: Q26732 | D26: AC CALDERONI* | E26: ONE GALLON NATURAL SYRUP OAKTOWN OLD FASHIONED ROOT BEER FOR CANS | F26: Can Raw Materials | G26: Accounts Payable (A/P) | H26: 32.82 | I26: 174826.63
A27: 05/14/2025 | B27: Bill | C27: Q26732 | D27: AC CALDERONI* | E27: 1 GALLON HANGAR 25 COLA IN TOTAL OUNCES = 128 OUNCES = 1 GALLON | F27: Can Raw Materials | G27: Accounts Payable (A/P) | H27: 228 | I27: 175054.63
A28: 05/14/2025 | B28: Bill | C28: Q26732 | D28: AC CALDERONI* | E28: freight | F28: Can Raw Materials | G28: Accounts Payable (A/P) | H28: 98.28 | I28: 175152.91
A29: 05/15/2025 | B29: Bill | C29: 123179576 | D29: TFC LLC | F29: Can Raw Materials | G29: Accounts Payable (A/P) | H29: 2000 | I29: 177152.91
A30: 05/23/2025 | B30: Bill | C30: 123309151 | D30: TFC LLC | F30: Can Raw Materials | G30: Accounts Payable (A/P) | H30: 2000 | I30: 179152.91
A31: 05/27/2025 | B31: Bill | C31: 123317960 | D31: TFC LLC | F31: Can Raw Materials | G31: Accounts Payable (A/P) | H31: 2000 | I31: 181152.91 | J31: =91*22 -> 2002 | K31: =J31*24 -> 48048 | L31: =H31/K31 -> 0.041625042 | M31: =J31/H31 -> 1.001
A32: 05/30/2025 | B32: Bill | C32: 123352230 | D32: TFC LLC | E32: five pallets Quantum to Brix | F32: Can Raw Materials | G32: Accounts Payable (A/P) | H32: 1295 | I32: 222590.23
A33: 06/05/2025 | B33: Expense | C33: BB-003 | D33: Craft Beverage Packaging Solutions | E33: May 2025 hours log | F33: Can Raw Materials | G33: Chase Business Checking | H33: 3271.32 | I33: 225861.55
H34: =SUM(H7:H33) -> 215861.55
H35: -12416.6 | K35: *$12416.60 should be left over for the excess sugar, five pallets, 251 bags of sugar for Alameda and 34 bags set aside for Shane, totaling 285 bags post run. 06/05/2025 email from Cali RE: 5/30 RE: End of week update
H36: =0.33*7*24*12*-1 -> -665.28 | K36: 7 layers of lemon lime leftover
H37: =H34+H35+H36 -> 202779.67 | K37: Total run cost
H38: ='Post run totals from Cali 06.05'!E29 -> 9712 | K38: Total Cases | L38: should have had a higher yeild from the 10499 we orderded
H39: =H37/H38 -> 20.879291 | K39: Price per case
A43: 06/14/2025 | B43: Journal Entry | C43: 1577 | F43: Can Raw Materials | H43: -203369.87 | I43: 12491.68
A44: 06/15/2025 | B44: Journal Entry | C44: 1578 | E44: credit for first run rate adjustment - see Sky's note to Calli in Trello | F44: Can Raw Materials | H44: 5997.6 | I44: 18489.28
G48: 45751
...

Sheet Quantum Run 04042025
A3: Row Labels | B3: Sum of Quantity
A4: 24P121091 HANGAR 25 DIET COLA CASE | B4: 480
A5: 24P126121 HANGAR 25 COLA CASE | B5: 695
A6: 24P126141 CABLE CAR LEMON LIME CASE | B6: 387
A7: 24P126151 OAKTOWN ROOTBEER CASE | B7: 557
A8: 24P126471 LOST ISLAND GINGER BEER CASE | B8: 37
A9: 24P126481 GOLDEN GATE ORANGE CASE | B9: 186
A10: Grand Total | B10: 2342
A14: Crème is approx 5% of sales
F25: July | G25: August | H25: September | I25: October | J25: November | K25: December | L25: January | M25: February | N25: Total Thru January | O25: Total Thru Feb
F26: 1000 | G26: =F26+100 -> 1100 | H26: =G26+100 -> 1200 | I26: =H26+100 -> 1300 | J26: =I26+100 -> 1400 | K26: =J26+100 -> 1500 | L26: =K26+100 -> 1600 | M26: =L26+100 -> 1700 | P26: Tank Run | Q26: Feb | R26: January
A27: =A4 -> 24P121091 HANGAR 25 DIET COLA CASE | B27: =B4 -> 480 | D27: =B27/$B$33 -> 0.1926937 | E27: =D28 -> 0.27900442 | F27: =F$26*$E27 -> 279.00442 | G27: =G$26*$E27 -> 306.90486 | H27: =H$26*$E27 -> 334.8053 | I27: =I$26*$E27 -> 362.70574 | J27: =J$26*$E27 -> 390.60618 | K27: =K$26*$E27 -> 418.50662 | L27: =L$26*$E27 -> 446.40707 | M27: =M$26*$E27 -> 474.30751 | N27: =SUM(F27:L27) -> 2538.9402 | O27: =SUM(F27:M27) -> 3013.2477 | P27: ='Quantum Run 04042025'!#REF! -> #REF! | Q27: =O27/P27 -> #REF! | R27: =N27/$P$27 -> #REF! | AF27: Tanks | AH27: Jan
A28: =A5 -> 24P126121 HANGAR 25 COLA CASE | B28: =B5 -> 695 | D28: =B28/$B$33 -> 0.27900442 | E28: =D30 -> 0.22360498 | F28: =F$26*$E28 -> 223.60498 | G28: =G$26*$E28 -> 245.96548 | H28: =H$26*$E28 -> 268.32597 | I28: =I$26*$E28 -> 290.68647 | J28: =J$26*$E28 -> 313.04697 | K28: =K$26*$E28 -> 335.40747 | L28: =L$26*$E28 -> 357.76796 | M28: =M$26*$E28 -> 380.12846 | N28: =SUM(F28:L28) -> 2034.8053 | O28: =SUM(F28:M28) -> 2414.9338 | P28: ='Quantum Run 04042025'!#REF! -> #REF! | Q28: =O28/P28 -> #REF! | R28: =N28/$P$27 -> #REF! | AF28: Partial | AG28: Full | AH28: Units | AI28: Cases
A29: =A6 -> 24P126141 CABLE CAR LEMON LIME CASE | B29: =B6 -> 387 | D29: =B29/$B$33 -> 0.15535929 | E29: =D27 -> 0.1926937 | F29: =F$26*$E29 -> 192.6937 | G29: =G$26*$E29 -> 211.96307 | H29: =H$26*$E29 -> 231.23244 | I29: =I$26*$E29 -> 250.50181 | J29: =J$26*$E29 -> 269.77118 | K29: =K$26*$E29 -> 289.04055 | L29: =L$26*$E29 -> 308.30992 | M29: =M$26*$E29 -> 327.57929 | N29: =SUM(F29:L29) -> 1753.5126 | O29: =SUM(F29:M29) -> 2081.0919 | P29: ='Quantum Run 04042025'!#REF! -> #REF! | Q29: =O29/P29 -> #REF! | R29: =N29/$P$27 -> #REF! | AE29: Cola | AF29: 2.4304227 | AH29: =AF29*26666 -> 64809.652 | AI29: =AH29/24 -> 2700.4022
A30: =A7 -> 24P126151 OAKTOWN ROOTBEER CASE | B30: =B7 -> 557 | D30: =B30/$B$33 -> 0.22360498 | E30: =D29 -> 0.15535929 | F30: =F$26*$E30 -> 155.35929 | G30: =G$26*$E30 -> 170.89522 | H30: =H$26*$E30 -> 186.43115 | I30: =I$26*$E30 -> 201.96708 | J30: =J$26*$E30 -> 217.50301 | K30: =K$26*$E30 -> 233.03894 | L30: =L$26*$E30 -> 248.57487 | M30: =M$26*$E30 -> 264.1108 | N30: =SUM(F30:L30) -> 1413.7696 | O30: =SUM(F30:M30) -> 1677.8804 | P30: ='Quantum Run 04042025'!#REF! -> #REF! | Q30: =O30/P30 -> #REF! | R30: =N30/$P$27 -> #REF! | AE30: Rootbeer | AF30: 1.9478352 | AH30: =AF30*26666 -> 51940.973 | AI30: =AH30/24 -> 2164.2072
A31: =A8 -> 24P126471 LOST ISLAND GINGER BEER CASE | B31: =B9 -> 186 | D31: =B31/$B$33 -> 0.074668808 | E31: =D32 -> 0.074668808 | F31: =F$26*$E31 -> 74.668808 | G31: =G$26*$E31 -> 82.135688 | H31: =H$26*$E31 -> 89.602569 | I31: =I$26*$E31 -> 97.06945 | J31: =J$26*$E31 -> 104.53633 | K31: =K$26*$E31 -> 112.00321 | L31: =L$26*$E31 -> 119.47009 | M31: =M$26*$E31 -> 126.93697 | N31: =SUM(F31:L31) -> 679.48615 | O31: =SUM(F31:M31) -> 806.42312 | P31: ='Quantum Run 04042025'!#REF! -> #REF! | Q31: =O31/P31 -> #REF! | R31: =N31/$P$27 -> #REF! | AE31: Diet | AF31: 1.6785653 | AH31: =AF31*26666 -> 44760.623 | AI31: =AH31/24 -> 1865.026
A32: =A9 -> 24P126481 GOLDEN GATE ORANGE CASE | B32: =B9 -> 186 | D32: =B32/$B$33 -> 0.074668808 | E32: =D31 -> 0.074668808 | F32: =F$26*$E32 -> 74.668808 | G32: =G$26*$E32 -> 82.135688 | H32: =H$26*$E32 -> 89.602569 | I32: =I$26*$E32 -> 97.06945 | J32: =J$26*$E32 -> 104.53633 | K32: =K$26*$E32 -> 112.00321 | L32: =L$26*$E32 -> 119.47009 | M32: =M$26*$E32 -> 126.93697 | N32: =SUM(F32:L32) -> 679.48615 | O32: =SUM(F32:M32) -> 806.42312 | P32: ='Quantum Run 04042025'!#REF! -> #REF! | Q32: =O32/P32 -> #REF! | R32: =N32/$P$27 -> #REF! | AE32: Lemon Lime | AF32: 1.3533433 | AH32: =AF32*26666 -> 36088.252 | AI32: =AH32/24 -> 1503.6772
B33: =SUM(B27:B32) -> 2491 | O33: =SUM(O27:O32) -> 10800 | Q33: =SUM(Q27:Q32) -> #REF! | R33: =SUM(R27:R32) -> #REF! | AE33: Orange | AF33: 0.65044406 | AH33: =AF33*26666 -> 17344.741 | AI33: =AH33/24 -> 722.69756
AD34: Ginger beer | AE34: 0.65044406 | AG34: =AE34*26666 -> 17344.741 | AH34: =AG34/24 -> 722.69756
AD35: Total | AE35: =SUM(AE29:AE34) -> 0.65044406 | AG35: =SUM(AG29:AG34) -> 17344.741 | AH35: =AG35/24 -> 722.69756
A36: Goal (12oz Units) | B36: 202300 | D36: based on 04/04 email from JT
A37: Run Increments (gallons) | B37: 1000 | D37: jason@quantumcanning.com
A38: Units per 1000 gallon runs | B38: =(B37*128)/12 -> 10666.667
B41: Units (out of 202,300) | C41: % | D41: 1000 gal increments | E41: Cases | F41: Finished Ounces | G41: Syrup Oz (5to1) | H41: Syrup Gallons
A42: Cola | B42: =C42*$B$36 -> 55085.254 | C42: 0.27229488 | D42: =B42/$B$38 -> 5.1642425 | E42: =B42/24 -> 2295.2189 | F42: =B42*12 -> 661023.05 | G42: =F42/6 -> 110170.51 | H42: =G42/128 -> 860.70709
A43: Rootbeer | B43: =C43*$B$36 -> 44147.462 | C43: 0.21822769 | D43: =B43/$B$38 -> 4.1388246 | E43: =B43/24 -> 1839.4776 | F43: =B43*12 -> 529769.55 | G43: =F43/6 -> 88294.925 | H43: =G43/128 -> 689.8041
A44: Diet | B44: =C44*$B$36 -> 38044.492 | C44: 0.18805977 | D44: =B44/$B$38 -> 3.5666711 | E44: =B44/24 -> 1585.1872 | F44: =B44*12 -> 456533.9 | G44: =F44/6 -> 76088.984 | H44: =G44/128 -> 594.44518 | I44: =F44/128 -> 3566.6711
A45: Lemon Lime | B45: =C45*$B$36 -> 30673.372 | C45: 0.15162319 | D45: =B45/$B$38 -> 2.8756286 | E45: =B45/24 -> 1278.0571 | F45: =B45*12 -> 368080.46 | G45: =F45/6 -> 61346.743 | H45: =G45/128 -> 479.27143
A46: Orange | B46: =C46*$B$36 -> 14742.241 | C46: 0.072873162 | D46: =B46/$B$38 -> 1.3820851 | E46: =B46/24 -> 614.26002 | F46: =B46*12 -> 176906.89 | G46: =F46/6 -> 29484.481 | H46: =G46/128 -> 230.34751
A47: Ginger beer | B47: =C47*$B$36 -> 19607.18 | C47: 0.096921305 | D47: =B47/$B$38 -> 1.8381731 | E47: =B47/24 -> 816.96583 | F47: =B47*12 -> 235286.16 | G47: =F47/6 -> 39214.36 | H47: =G47/128 -> 306.36219
A48: Total | B48: =SUM(B42:B47) -> 202300 | C48: =SUM(C42:C47) -> 1 | D48: =SUM(D42:D47) -> 18.965625 | E48: =SUM(E42:E47) -> 8429.1667 | F48: =SUM(F42:F47) -> 2427600 | G48: =SUM(G42:G47) -> 404600 | H48: =SUM(H42:H47) -> 3160.9375
A53: sent to sky 03/27 | B53: Units (out of 250k) | C53: 1000 gal increments | D53: Rounded down | E53: Units | F53: Cases | G53: Finished Ounces | H53: Syrup Oz (5to1) | I53: Syrup Gallons
A54: Cola | B54: 69,751 | C54: 6.5 | D54: 6 | E54: 64,000 | F54: 2,667 | G54: 768,000 | H54: 128,000 | I54: 1,000
A55: Rootbeer | B55: 55,901 | C55: 5.2 | D55: 5 | E55: 53,333 | F55: 2,222 | G55: 640,000 | H55: 106,667 | I55: 833
A56: Diet | B56: 48,173 | C56: 4.5 | D56: 4 | E56: 42,667 | F56: 1,778 | G56: 512,000 | H56: 85,333 | I56: 667
A57: Lemon Lime | B57: 38,840 | C57: 3.6 | D57: 3 | E57: 32,000 | F57: 1,333 | G57: 384,000 | H57: 64,000 | I57: 500
A58: Orange | B58: 18,667 | C58: 1.8 | D58: 2 | E58: 21,333 | F58: 889 | G58: 256,000 | H58: 42,667 | I58: 333
A59: Ginger beer | B59: 18,667 | C59: 1.8 | D59: 3 | E59: 32,000 | F59: 1,333 | G59: 384,000 | H59: 64,000 | I59: 500
A60: Total | B60: 250,000 | C60: 23.4 | D60: 23 | E60: 245,333 | F60: 10,222 | G60: 2,944,000 | H60: 490,667 | I60: 3,833
A64: PO to Craft Beverage Warehouse 04/14/2025 | B64: Units (out of 250k) | C64: 1000 gal increments | D64: Rounded down | E64: Units | F64: Cases | G64: Finished Ounces | H64: Syrup Oz (5to1) | I64: Syrup Gallons
...

Sheet Post run totals from Cali 06.05
B1: Lot | C1: SKU | D1: Cans
B2: Q0375 | C2: Cola #1 | D2: 10920 | G2: 0.61 | H2: Calli's Can Numbers | I2: Quantum's Can Numbers | M2: Cans orderd | N2: Yeild | O2: Goal | P2: Dif
B3: Q0379 | C3: Cola #2 | D3: 12024 | G3: Full Can Total | H3: =D7+D12+D15+D18+D21+D26 -> 232968 | I3: =D26+D21+D18+D15+D12+E7 -> 233088 | J3: =H3/24 -> 9707 | K3: =I3/24 -> 9712 | M3: 251998 | N3: =H3/M3 -> 0.92448353 | O3: 450000 | P3: =450000-I3 -> 216912 | Q3: =P3*1.05 -> 227757.6
B4: Q0390 | C4: Cola #3 | D4: 20184 | G4: Run Cost at $0.61/can | H4: =H3*G2 -> 142110.48 | I4: =I3*G2 -> 142183.68 | M4: =M3/24 -> 10499.917
B5: Q0393 | C5: Cola #4 | D5: 10920 | G5: Velcorin | H5: =H3*0.02 -> 4659.36 | I5: =I3*0.02 -> 4661.76
B6: Q0397 | C6: Cola #5 | D6: 9552 | E6: Quantum Invoiced | G6: Dunnage | H6: =(114*50) -> 5700 | I6: =(114*50) -> 5700
C7: TOTAL COLA | D7: =SUM(D2:D6) -> 63600 | E7: 63720 | F7: =E7/24 -> 2655 | G7: Deposit Credit #1415 | H7: -62114.06 | I7: -62114.06
B8: Q0399 | C8: Diet Cola #1 | D8: 21120 | G8: Deposit Credit #1430 | H8: -62630.06 | I8: -62630.06
B9: Q0401 | C9: Diet Cola #2 | D9: 12696 | G9: Balance Due | H9: =SUM(H4:H8) -> 27725.72 | I9: =SUM(I4:I8) -> 27801.32
B10: Q0401B | C10: Diet Cola #3 | D10: 12696 | G10: Paid | H10: -40142.32 | I10: -40142.32
B11: Q0376 | C11: Diet Cola- Dumped | D11: not packaged | G11: Offset Needed | H11: =SUM(H9:H10) -> -12416.6 | I11: =SUM(I9:I10) -> -12341
C12: TOTAL DIET COLA | D12: =SUM(D8:D10) -> 46512 | E12: =D12/24 -> 1938
B13: Q0378 | C13: Ginger Beer #1 | D13: 10248
B14: Q0394 | C14: Ginger Beer #2 | D14: 8256 | M14: 0.37
C15: TOTAL GINGER BEER | D15: =SUM(D13:D14) -> 18504 | E15: =D15/24 -> 771 | M15: 0.125
B16: Q0373 | C16: Lemon Lime #1 | D16: 12912 | M16: =SUM(M14:M15) -> 0.495
B17: Q0387 | C17: Lemon Lime #2 | D17: 19656
C18: TOTAL LEMON LIME | D18: =SUM(D16:D17) -> 32568 | E18: =D18/24 -> 1357
B19: Q0374 | C19: Orange #1 | D19: 10392
B20: Q0398 | C20: Orange #2 | D20: 8208
C21: TOTAL ORANGE | D21: =SUM(D19:D20) -> 18600 | E21: =D21/24 -> 775
B22: Q0385 | C22: Root Beer #2 | D22: 19656
B23: Q0386 | C23: Root Beer #3 | D23: 10344
B24: Q0396 | C24: Root Beer #4 | D24: 11832
B25: Q0377 | C25: Rootbeer #1 | D25: 11352
C26: TOTAL ROOT BEER | D26: =SUM(D22:D25) -> 53184 | E26: =D26/24 -> 2216
C27: TOTAL ALL SKUS | D27: =D26+D21+D18+D15+D12+D7 -> 232968
E29: =SUM(E12:E26)+F7 -> 9712

Sheet POSTRUN INVEN FRM CALI 06.05
A1: Canning Client | B1: Alameda Soda
A2: Inventoried by | B2: CH RG
A3: Verified by
A4: Last Date Inventoried | B4: 45806
A7: ON-HAND INGREDIENTS AND MATERIALS
A8: CONSUMABLES (cans, ends, trays, etc) | B8: Date Arrived | C8: Staff Initial | D8: Supplier | E8: Units (lbs/kg/g) | F8: Qty | G8: Per each | H8: Pallets | I8: Total On Site | J8: Item
A9: Cola Cans | I9: 0 | J9: =A9 -> Cola Cans
A10: Diet Cola Cans | I10: 0 | J10: =A10 -> Diet Cola Cans
A11: Orange Cans | I11: 0 | J11: =A11 -> Orange Cans
A12: Root Beer Cans | I12: 0 | J12: =A12 -> Root Beer Cans
A13: Ginger Beer Cans | I13: 0 | J13: =A13 -> Ginger Beer Cans
A14: Lemon Lime Cans | I14: =7*506 -> 3542 | J14: =A14 -> Lemon Lime Cans
A15: Ends | I15: 0 | J15: =A15 -> Ends
A16: Trays | I16: 0 | J16: =A16 -> Trays
A18: INGREDIENTS | B18: Date Arrived | C18: Staff Initial | D18: Supplier | E18: Lot Code | F18: BBD | G18: Units (lbs/kg/g) | H18: Qty | I18: Per each | J18: Sum | K18: LBS | L18: KG to lbs | M18: Total LBS | N18: COA? | O18: =A18 -> INGREDIENTS
A19: I70 Cola Flavor Partial | B19: 45797 | C19: CH | D19: Boggini | E19: 2-068 | F19: 46100 | G19: lbs | H19: 1 | I19: =9.55-0.3 -> 9.25 | J19: =I19*H19 -> 9.25 | K19: =J19 -> 9.25 | M19: =SUM(K19:L19) -> 9.25 | N19: Yes | O19: =A19 -> I70 Cola Flavor Partial
A20: I70 Cola Flavor Full | B20: 45797 | C20: CH | D20: Boggini | E20: 2-068 | F20: 46100 | G20: lbs | H20: 1 | I20: =10.55-0.3 -> 10.25 | J20: =I20*H20 -> 10.25 | K20: =J20 -> 10.25 | M20: =SUM(K20:L20) -> 10.25 | O20: =A20 -> I70 Cola Flavor Full
A21: TOTAL COLA FLAVOR | O21: =A21 -> TOTAL COLA FLAVOR
O22: =A22 -> 0
A23: Hot Pepper Flavor Full | B23: 45762 | C23: CH | D23: Dayton Flavors | E23: 17874 | F23: 46123 | G23: lbs | H23: 1 | I23: =9-0.3 -> 8.7 | J23: =I23*H23 -> 8.7 | K23: =J23 -> 8.7 | M23: =SUM(K23:L23) -> 8.7 | N23: Yes | O23: =A23 -> Hot Pepper Flavor Full
A24: Hot Pepper Flavor Partial | B24: 45762 | C24: CH | D24: Dayton Flavors | E24: 17874 | F24: 46123 | G24: lbs | H24: 1 | I24: =3.95-0.3 -> 3.65 | J24: =I24*H24 -> 3.65 | K24: =J24 -> 3.65 | M24: =SUM(K24:L24) -> 3.65 | N24: Yes | O24: =A24 -> Hot Pepper Flavor Partial
A25: TOTAL HOT PEPPER FLAVOR | K25: =J25 -> 0 | M25: =M24 -> 3.65 | O25: =A25 -> TOTAL HOT PEPPER FLAVOR
K26: =J26 -> 0 | O26: =A26 -> 0
A27: Lemon UP Flavor | B27: 45768 | C27: CH | D27: Boggini | E27: 2-092 | F27: 46120 | G27: lbs | H27: 1 | I27: =3.5-0.3 -> 3.2 | J27: =I27*H27 -> 3.2 | K27: =J27 -> 3.2 | M27: =SUM(K27:L27) -> 3.2 | N27: Yes | O27: =A27 -> Lemon UP Flavor
A28: TOTAL LEMON UP | K28: =J28 -> 0 | M28: =M27 -> 3.2 | O28: =A28 -> TOTAL LEMON UP
K29: =J29 -> 0 | O29: =A29 -> 0
A30: Citric Acid | B30: 45768 | C30: CH | D30: COFCO Biochemical CO LTD | E30: AA-24112237FG | F30: 46711 | G30: lbs | H30: 1 | I30: =7.15-0.2 -> 6.95 | J30: =I30*H30 -> 6.95 | K30: =J30 -> 6.95 | M30: =SUM(K30:L30) -> 6.95 | N30: Yes | O30: =A30 -> Citric Acid
A31: TOTAL CITRIC ACID | K31: =J31 -> 0 | M31: =M30 -> 6.95 | O31: =A31 -> TOTAL CITRIC ACID
K32: =J32 -> 0 | O32: =A32 -> 0
A33: Sodium Citrate | B33: 45768 | C33: CH | D33: Daffodil Pharmachem | E33: SC2312009 | F33: 46692 | G33: lbs | H33: 1 | I33: 2.35 | J33: =I33*H33 -> 2.35 | K33: =J33 -> 2.35 | M33: =SUM(K33:L33) -> 2.35 | N33: Yes | O33: =A33 -> Sodium Citrate
A34: TOTAL SODIUM CITRATE | K34: =J34 -> 0 | M34: =M33 -> 2.35 | O34: =A34 -> TOTAL SODIUM CITRATE
K35: =J35 -> 0 | O35: =A35 -> 0
A36: Erythritol | B36: 45798 | C36: CH | D36: Bulk Supplements | E36: R2408205 | F36: 46173 | G36: lbs | H36: 1 | I36: 0.85 | J36: =I36*H36 -> 0.85 | K36: =J36 -> 0.85 | M36: =SUM(K36:L36) -> 0.85 | N36: Yes | O36: =A36 -> Erythritol
A37: TOTAL ERYTHRITOL | K37: =J37 -> 0 | M37: =M36 -> 0.85 | O37: =A37 -> TOTAL ERYTHRITOL
A39: Sodium Gluconate | B39: checking | C39: RG | D39: checking | E39: 5000508/1.1 | F39: checking | G39: lbs | H39: 1 | I39: 27.55 | J39: =I39*H39 -> 27.55 | K39: =J39 -> 27.55 | M39: =SUM(K39:L39) -> 27.55 | N39: Yes | O39: =A39 -> Sodium Gluconate
A40: TOTAL SODIUM GLUCONATE | K40: =J40 -> 0 | M40: =M39 -> 27.55 | O40: =A40 -> TOTAL SODIUM GLUCONATE
K41: =J41 -> 0 | O41: =A41 -> 0
A42: Caramel Color | B42: 45768 | C42: CH | D42: Sethness Roquette | F42: 46233 | G42: lbs | H42: 1 | I42: =9.25-0.3 -> 8.95 | J42: =I42*H42 -> 8.95 | K42: =J42 -> 8.95 | M42: =SUM(K42:L42) -> 8.95 | N42: Yes | O42: =A42 -> Caramel Color
A43: TOTAL CARAMEL COLOR | K43: =J43 -> 0 | M43: =M42 -> 8.95 | O43: =A43 -> TOTAL CARAMEL COLOR
K44: =J44 -> 0 | O44: =A44 -> 0
...

Sheet DELETE Quantum Run 03-25-2025 
A3: Row Labels | B3: Sum of Quantity
A4: 24P121091 HANGAR 25 DIET COLA CASE | B4: 480
A5: 24P126121 HANGAR 25 COLA CASE | B5: 695
A6: 24P126141 CABLE CAR LEMON LIME CASE | B6: 387
A7: 24P126151 OAKTOWN ROOTBEER CASE | B7: 557
A8: 24P126471 LOST ISLAND GINGER BEER CASE | B8: 37
A9: 24P126481 GOLDEN GATE ORANGE CASE | B9: 186
A10: Grand Total | B10: 2342
A14: Crème is approx 5% of sales
H25: July | I25: August | J25: September | K25: October | L25: November | M25: December | N25: January | O25: February | P25: Total Thru January | Q25: Total Thru Feb
H26: 1000 | I26: =H26+100 -> 1100 | J26: =I26+100 -> 1200 | K26: =J26+100 -> 1300 | L26: =K26+100 -> 1400 | M26: =L26+100 -> 1500 | N26: =M26+100 -> 1600 | O26: =N26+100 -> 1700 | R26: Tank Run | S26: Feb | T26: January
A27: =A4 -> 24P121091 HANGAR 25 DIET COLA CASE | B27: =B4 -> 480 | D27: =B27/$B$33 -> 0.1926937 | F27: Cola | G27: =D28 -> 0.27900442 | H27: =H$26*$G27 -> 279.00442 | I27: =I$26*$G27 -> 306.90486 | J27: =J$26*$G27 -> 334.8053 | K27: =K$26*$G27 -> 362.70574 | L27: =L$26*$G27 -> 390.60618 | M27: =M$26*$G27 -> 418.50662 | N27: =N$26*$G27 -> 446.40707 | O27: =O$26*$G27 -> 474.30751 | P27: =SUM(H27:N27) -> 2538.9402 | Q27: =SUM(H27:O27) -> 3013.2477 | R27: ='DELETE Quantum Run 03-25-2025 '!$A$79 -> 1111.1111 | S27: =Q27/R27 -> 2.7119229 | T27: =P27/$R$27 -> 2.2850462 | AH27: Tanks | AJ27: Jan
A28: =A5 -> 24P126121 HANGAR 25 COLA CASE | B28: =B5 -> 695 | D28: =B28/$B$33 -> 0.27900442 | F28: Rootbeer | G28: =D30 -> 0.22360498 | H28: =H$26*$G28 -> 223.60498 | I28: =I$26*$G28 -> 245.96548 | J28: =J$26*$G28 -> 268.32597 | K28: =K$26*$G28 -> 290.68647 | L28: =L$26*$G28 -> 313.04697 | M28: =M$26*$G28 -> 335.40747 | N28: =N$26*$G28 -> 357.76796 | O28: =O$26*$G28 -> 380.12846 | P28: =SUM(H28:N28) -> 2034.8053 | Q28: =SUM(H28:O28) -> 2414.9338 | R28: ='DELETE Quantum Run 03-25-2025 '!$A$79 -> 1111.1111 | S28: =Q28/R28 -> 2.1734404 | T28: =P28/$R$27 -> 1.8313248 | AH28: Partial | AI28: Full | AJ28: Units | AK28: Cases
A29: =A6 -> 24P126141 CABLE CAR LEMON LIME CASE | B29: =B6 -> 387 | D29: =B29/$B$33 -> 0.15535929 | F29: Diet | G29: =D27 -> 0.1926937 | H29: =H$26*$G29 -> 192.6937 | I29: =I$26*$G29 -> 211.96307 | J29: =J$26*$G29 -> 231.23244 | K29: =K$26*$G29 -> 250.50181 | L29: =L$26*$G29 -> 269.77118 | M29: =M$26*$G29 -> 289.04055 | N29: =N$26*$G29 -> 308.30992 | O29: =O$26*$G29 -> 327.57929 | P29: =SUM(H29:N29) -> 1753.5126 | Q29: =SUM(H29:O29) -> 2081.0919 | R29: ='DELETE Quantum Run 03-25-2025 '!$A$79 -> 1111.1111 | S29: =Q29/R29 -> 1.8729827 | T29: =P29/$R$27 -> 1.5781614 | AG29: Cola | AH29: 2.4304227 | AJ29: =AH29*26666 -> 64809.652 | AK29: =AJ29/24 -> 2700.4022
A30: =A7 -> 24P126151 OAKTOWN ROOTBEER CASE | B30: =B7 -> 557 | D30: =B30/$B$33 -> 0.22360498 | F30: Lemon Lime | G30: =D29 -> 0.15535929 | H30: =H$26*$G30 -> 155.35929 | I30: =I$26*$G30 -> 170.89522 | J30: =J$26*$G30 -> 186.43115 | K30: =K$26*$G30 -> 201.96708 | L30: =L$26*$G30 -> 217.50301 | M30: =M$26*$G30 -> 233.03894 | N30: =N$26*$G30 -> 248.57487 | O30: =O$26*$G30 -> 264.1108 | P30: =SUM(H30:N30) -> 1413.7696 | Q30: =SUM(H30:O30) -> 1677.8804 | R30: ='DELETE Quantum Run 03-25-2025 '!$A$79 -> 1111.1111 | S30: =Q30/R30 -> 1.5100923 | T30: =P30/$R$27 -> 1.2723926 | AG30: Rootbeer | AH30: 1.9478352 | AJ30: =AH30*26666 -> 51940.973 | AK30: =AJ30/24 -> 2164.2072
A31: =A8 -> 24P126471 LOST ISLAND GINGER BEER CASE | B31: =B9 -> 186 | D31: =B31/$B$33 -> 0.074668808 | F31: Orange | G31: =D32 -> 0.074668808 | H31: =H$26*$G31 -> 74.668808 | I31: =I$26*$G31 -> 82.135688 | J31: =J$26*$G31 -> 89.602569 | K31: =K$26*$G31 -> 97.06945 | L31: =L$26*$G31 -> 104.53633 | M31: =M$26*$G31 -> 112.00321 | N31: =N$26*$G31 -> 119.47009 | O31: =O$26*$G31 -> 126.93697 | P31: =SUM(H31:N31) -> 679.48615 | Q31: =SUM(H31:O31) -> 806.42312 | R31: ='DELETE Quantum Run 03-25-2025 '!$A$79 -> 1111.1111 | S31: =Q31/R31 -> 0.72578081 | T31: =P31/$R$27 -> 0.61153754 | AG31: Diet | AH31: 1.6785653 | AJ31: =AH31*26666 -> 44760.623 | AK31: =AJ31/24 -> 1865.026
A32: =A9 -> 24P126481 GOLDEN GATE ORANGE CASE | B32: =B9 -> 186 | D32: =B32/$B$33 -> 0.074668808 | F32: *Ginger beer | G32: =D31 -> 0.074668808 | H32: =H$26*$G32 -> 74.668808 | I32: =I$26*$G32 -> 82.135688 | J32: =J$26*$G32 -> 89.602569 | K32: =K$26*$G32 -> 97.06945 | L32: =L$26*$G32 -> 104.53633 | M32: =M$26*$G32 -> 112.00321 | N32: =N$26*$G32 -> 119.47009 | O32: =O$26*$G32 -> 126.93697 | P32: =SUM(H32:N32) -> 679.48615 | Q32: =SUM(H32:O32) -> 806.42312 | R32: ='DELETE Quantum Run 03-25-2025 '!$A$79 -> 1111.1111 | S32: =Q32/R32 -> 0.72578081 | T32: =P32/$R$27 -> 0.61153754 | AG32: Lemon Lime | AH32: 1.3533433 | AJ32: =AH32*26666 -> 36088.252 | AK32: =AJ32/24 -> 1503.6772
B33: =SUM(B27:B32) -> 2491 | Q33: =SUM(Q27:Q32) -> 10800 | S33: =SUM(S27:S32) -> 9.72 | T33: =SUM(T27:T32) -> 8.19 | AG33: Orange | AH33: 0.65044406 | AJ33: =AH33*26666 -> 17344.741 | AK33: =AJ33/24 -> 722.69756
F34: *Estimate | AF34: Ginger beer | AG34: 0.65044406 | AI34: =AG34*26666 -> 17344.741 | AJ34: =AI34/24 -> 722.69756
AF35: Total | AG35: =SUM(AG29:AG34) -> 0.65044406 | AI35: =SUM(AI29:AI34) -> 17344.741 | AJ35: =AI35/24 -> 722.69756
A36: Goal (12oz Units) | B36: 200000 | D36: based on 04/04 email from JT | E36: jason@quantumcanning.com
A37: Run Increments (gallons) | B37: 1000
A38: Units per 1000 gallon runs | B38: =(B37*128)/12 -> 10666.667
B41: Units (out of 200k) | C41: % | D41: 1000 gal increments | E41: Exact Units | F41: Units | G41: Cases | H41: Finished Ounces | I41: Syrup Oz (5to1) | J41: Syrup Gallons
A42: Cola | B42: =$B$36*D28 -> 55800.883 | C42: =B42/$B$48 -> 0.27229488 | D42: =B42/$B$38 -> 5.2313328 | E42: =D42 -> 5.2313328 | F42: =E42*$B$38 -> 55800.883 | G42: =F42/24 -> 2325.0368 | H42: =F42*12 -> 669610.6 | I42: =H42/6 -> 111601.77 | J42: =I42/128 -> 871.8888
A43: Rootbeer | B43: =$B$36*D30 -> 44720.996 | C43: =B43/$B$48 -> 0.21822769 | D43: =B43/$B$38 -> 4.1925933 | E43: =D43 -> 4.1925933 | F43: =E43*$B$38 -> 44720.996 | G43: =F43/24 -> 1863.3748 | H43: =F43*12 -> 536651.95 | I43: =H43/6 -> 89441.991 | J43: =I43/128 -> 698.76556
A44: Diet | B44: =$B$36*D27 -> 38538.739 | C44: =B44/$B$48 -> 0.18805977 | D44: =B44/$B$38 -> 3.6130068 | E44: =D44 -> 3.6130068 | F44: =E44*$B$38 -> 38538.739 | G44: =F44/24 -> 1605.7808 | H44: =F44*12 -> 462464.87 | I44: =H44/6 -> 77077.479 | J44: =I44/128 -> 602.1678
A45: Lemon Lime | B45: =$B$36*D29 -> 31071.859 | C45: =B45/$B$48 -> 0.15162319 | D45: =B45/$B$38 -> 2.9129868 | E45: =D45 -> 2.9129868 | F45: =E45*$B$38 -> 31071.859 | G45: =F45/24 -> 1294.6608 | H45: =F45*12 -> 372862.3 | I45: =H45/6 -> 62143.717 | J45: =I45/128 -> 485.49779
A46: Orange | B46: =$B$36*D32 -> 14933.762 | C46: =B46/$B$48 -> 0.072873162 | D46: =B46/$B$38 -> 1.4000401 | E46: =D46 -> 1.4000401 | F46: =E46*$B$38 -> 14933.762 | G46: =F46/24 -> 622.24006 | H46: =F46*12 -> 179205.14 | I46: =H46/6 -> 29867.523 | J46: =I46/128 -> 233.34002
A47: Ginger beer | B47: =B46*1.33 -> 19861.903 | C47: =B47/$B$48 -> 0.096921305 | D47: =B47/$B$38 -> 1.8620534 | E47: 2 | F47: =E47*$B$38 -> 21333.333 | G47: =F47/24 -> 888.88889 | H47: =F47*12 -> 256000 | I47: =H47/6 -> 42666.667 | J47: =I47/128 -> 333.33333
A48: Total | B48: =SUM(B42:B47) -> 204928.14 | D48: =SUM(D42:D47) -> 19.212013 | E48: =SUM(E42:E47) -> 19.34996 | F48: =SUM(F42:F47) -> 206399.57 | G48: =SUM(G42:G47) -> 8599.9822 | H48: =SUM(H42:H47) -> 2476794.9 | I48: =SUM(I42:I47) -> 412799.14 | J48: =SUM(J42:J47) -> 3224.9933
E50: Unit Cost | F50: 0.8 | G50: =F50*24 -> 19.2
E51: Total Run Cost | F51: =F48*F50 -> 165119.66
B54: Units (out of 250k) | D54: 1000 gal increments | E54: Rounded down | F54: Units | G54: Cases | H54: Finished Ounces | I54: Syrup Oz (5to1) | J54: Syrup Gallons
A55: Cola | B55: =B42 -> 55800.883 | D55: =B55/$B$38 -> 5.2313328 | E55: 6 | F55: =E55*$B$38 -> 64000 | G55: =F55/24 -> 2666.6667 | H55: =F55*12 -> 768000 | I55: =H55/6 -> 128000 | J55: =I55/128 -> 1000
A56: Rootbeer | B56: =B43 -> 44720.996 | D56: =B56/$B$38 -> 4.1925933 | E56: 5 | F56: =E56*$B$38 -> 53333.333 | G56: =F56/24 -> 2222.2222 | H56: =F56*12 -> 640000 | I56: =H56/6 -> 106666.67 | J56: =I56/128 -> 833.33333
A57: Diet | B57: =B44 -> 38538.739 | D57: =B57/$B$38 -> 3.6130068 | E57: 4 | F57: =E57*$B$38 -> 42666.667 | G57: =F57/24 -> 1777.7778 | H57: =F57*12 -> 512000 | I57: =H57/6 -> 85333.333 | J57: =I57/128 -> 666.66667
A58: Lemon Lime | B58: =B45 -> 31071.859 | D58: =B58/$B$38 -> 2.9129868 | E58: 3 | F58: =E58*$B$38 -> 32000 | G58: =F58/24 -> 1333.3333 | H58: =F58*12 -> 384000 | I58: =H58/6 -> 64000 | J58: =I58/128 -> 500
A59: Orange | B59: =B46 -> 14933.762 | D59: =B59/$B$38 -> 1.4000401 | E59: 2 | F59: =E59*$B$38 -> 21333.333 | G59: =F59/24 -> 888.88889 | H59: =F59*12 -> 256000 | I59: =H59/6 -> 42666.667 | J59: =I59/128 -> 333.33333
A60: Ginger beer | B60: =B47 -> 19861.903 | D60: =B60/$B$38 -> 1.8620534 | E60: 3 | F60: =E60*$B$38 -> 32000 | G60: =F60/24 -> 1333.3333 | H60: =F60*12 -> 384000 | I60: =H60/6 -> 64000 | J60: =I60/128 -> 500
...

Sheet 01-30-2025 Quantum Run
A1: Date | B1: Transaction Type | C1: Num | D1: Name | E1: Memo/Description | F1: Account | G1: Split | H1: Amount
A2: Beginning Balance | H2: 67
A3: 08/19/2024 | B3: Bill | C3: DC11519 | D3: DigiCan Printing LLC | E3: CAN HANGAR 25 COLA 12OZ SLEEK | F3: Can Raw Materials | G3: Accounts Payable (A/P) | H3: 6314.88
A4: 08/19/2024 | B4: Bill | C4: DC11519 | D4: DigiCan Printing LLC | E4: CAN CABLE CAR 12OZ SLEEK EMPTY | F4: Can Raw Materials | G4: Accounts Payable (A/P) | H4: 6314.88
A5: 08/19/2024 | B5: Bill | C5: DC11519 | D5: DigiCan Printing LLC | E5: CAN GOLDEN GATE ORANGE 12OZ SLEEK | F5: Can Raw Materials | G5: Accounts Payable (A/P) | H5: 6314.88
A6: 08/19/2024 | B6: Bill | C6: DC11519 | D6: DigiCan Printing LLC | E6: CAN OAKTOWN ROOT BEER 12OZ SLEEK EMPTY | F6: Can Raw Materials | G6: Accounts Payable (A/P) | H6: 6314.88
A7: 08/19/2024 | B7: Bill | C7: DC11519 | D7: DigiCan Printing LLC | E7: CAN OLD FOUNTAIN CREME 12OZ SLEEK EMPTY | F7: Can Raw Materials | G7: Accounts Payable (A/P) | H7: 6314.88
A8: 45614 | B8: Bill | C8: DC11519 | D8: DigiCan Printing LLC | E8: CAN OLD FOUNTAIN CREME 12OZ SLEEK EMPTY | F8: Can Raw Materials | G8: Accounts Payable (A/P) | H8: =I8*0.33 -> 6660.72 | I8: ='Excess worksheet 11-26-2024'!I14*24 -> 20184 | J8: units leftover from earlier production run
H9: =SUM(H2:H8) -> 38302.12
A11: 08/19/2024 | B11: Bill | C11: DC11519 | D11: DigiCan Printing LLC | E11: 202-LOE-BLK-12OZ SLEEK BLK CAN LIDS | F11: Can Raw Materials | G11: Accounts Payable (A/P) | H11: 6679.2
A12: 45614 | B12: Bill | C12: DC11519 | D12: DigiCan Printing LLC | E12: 202-LOE-BLK-12OZ SLEEK BLK CAN LIDS | F12: Can Raw Materials | G12: Accounts Payable (A/P) | H12: =I12*0.07 -> 353.22 | I12: 5046 | J12: units leftover from earlier production run
H13: =SUM(H11:H12) -> 7032.42
A15: 10/15/2024 | B15: Bill | C15: 26331 | D15: AC CALDERONI* | E15: ONE GALLON NATURAL SYRUP HANGAR 25 COLA FOR CANS | F15: Can Raw Materials | G15: Accounts Payable (A/P) | H15: 2620.8
A16: 10/15/2024 | B16: Bill | C16: 26331 | D16: AC CALDERONI* | E16: ONE GALLON NATURAL SYRUP CABLE CAR LEMON LIME FOR CANS | F16: Can Raw Materials | G16: Accounts Payable (A/P) | H16: 2706.6
A17: 10/15/2024 | B17: Bill | C17: 26331 | D17: AC CALDERONI* | E17: ONE GALLON NATURAL SYRUP OAKTOWN OLD FASHIONED ROOT BEER FOR CANS | F17: Can Raw Materials | G17: Accounts Payable (A/P) | H17: 2730
A18: 10/15/2024 | B18: Bill | C18: 26331 | D18: AC CALDERONI* | E18: ONE GALLON NATURAL SYRUP OLDE FOUNTAIN CRÈME FOR CANS | F18: Can Raw Materials | G18: Accounts Payable (A/P) | H18: 2901.6
A19: 10/15/2024 | B19: Bill | C19: 26331 | D19: AC CALDERONI* | E19: ONE GALLON NATURAL SYRUP GOLDEN GATE ORANGE FOR CANS | F19: Can Raw Materials | G19: Accounts Payable (A/P) | H19: 2901.6
A20: 10/15/2024 | B20: Bill | C20: 26331 | D20: AC CALDERONI* | E20: ONE GALLON NATURAL SYRUP GOLDEN GATE ORANGE FOR CANS | F20: Can Raw Materials | G20: Accounts Payable (A/P) | H20: 2901.6
A21: 45614 | B21: Bill | C21: 26331 | D21: AC CALDERONI* | E21: Leftover Syrup | F21: Can Raw Materials | G21: Accounts Payable (A/P) | H21: ='Excess worksheet 11-26-2024'!N34 -> 3116.5575 | I21: ='Excess worksheet 11-26-2024'!L34 -> 438.9375 | J21: units leftover from earlier production run
H22: =SUM(H15:H19) -> 13860.6
A24: 45657 | B24: Bill | C24: 121468733 | D24: TFC LLC | F24: Can Raw Materials | G24: Accounts Payable (A/P) | H24: 798 | J24: probably belongs on previous run
A25: 45679 | B25: Bill | C25: 01222431 | D25: Claassen Law Corp | F25: Can Raw Materials | G25: Accounts Payable (A/P) | H25: 1305 | J25: Legal fees?
A26: 45681 | B26: Bill | C26: 1366 | D26: Quantum Canning | F26: Can Raw Materials | G26: Accounts Payable (A/P) | H26: 4270.6
A27: 45685 | B27: Bill | C27: 121790334 | D27: TFC LLC | F27: Can Raw Materials | G27: Accounts Payable (A/P) | H27: 2095
A28: 45688 | B28: Bill | D28: Craft Beverage Packaging Solutions | F28: Can Raw Materials | G28: Accounts Payable (A/P) | H28: 472.5
A29: 45688 | B29: Bill | D29: Craft Beverage Packaging Solutions | E29: Total | F29: Can Raw Materials | G29: Accounts Payable (A/P) | H29: 262.5
A30: 45690 | B30: Expense | C30: 573125 | D30: ORTHODOX UNION | E30: Kosher Cost For Quantum | F30: Can Raw Materials | G30: Chase Business Checking | H30: 950
H31: =SUM(H24:H30) -> 10153.6
G34: Total Production Run 01/30/2025 | H34: =H31+H21+H12+H8 -> 20284.097
G38: 45614 | J38: Quantuum delivery - 01/30/2025 | K38: Cases | L38: Units
G39: Finished Cans | H39: =L45 -> 20016 | J39: Orange | K39: 127 | L39: =K39*24 -> 3048
J40: Cola | K40: 181 | L40: =K40*24 -> 4344
H41: Cost Per Can | J41: Lemon Lime | K41: 181 | L41: =K41*24 -> 4344
G42: Cans | H42: =H8/H39 -> 0.33276978 | J42: Cream Soda | K42: 173 | L42: =K42*24 -> 4152
G43: Lids | H43: =H12/H39 -> 0.017646882 | J43: Root Beer | K43: 172 | L43: =K43*24 -> 4128
G44: Fill | H44: =H26/H39 -> 0.21335931 | J44: Cases | K44: =SUM(K39:K43) -> 834
G45: Raw Ingredients | H45: =H21/H39 -> 0.15570331 | J45: Units | L45: =SUM(L39:L43) -> 20016
G46: OTHER COST | H46: =(H25+H30)/H34 -> 0.11117083
G47: Shipping | H47: =(H24+H26)/H39 -> 0.25322742
G48: Cartons | H48: =(H29+H28)/H34 -> 0.036235282 | J48: Raw Materials Account 02/06 | L48: 23689.27
...

Sheet 11-18-2024 Production Run
A1: Date | B1: Transaction Type | C1: Num | D1: Name | E1: Memo/Description | F1: Account | G1: Split | H1: Amount
A2: Beginning Balance | H2: 67
A3: 08/19/2024 | B3: Bill | C3: DC11519 | D3: DigiCan Printing LLC | E3: CAN HANGAR 25 COLA 12OZ SLEEK | F3: Can Raw Materials | G3: Accounts Payable (A/P) | H3: 6314.88
A4: 08/19/2024 | B4: Bill | C4: DC11519 | D4: DigiCan Printing LLC | E4: CAN CABLE CAR 12OZ SLEEK EMPTY | F4: Can Raw Materials | G4: Accounts Payable (A/P) | H4: 6314.88
A5: 08/19/2024 | B5: Bill | C5: DC11519 | D5: DigiCan Printing LLC | E5: CAN GOLDEN GATE ORANGE 12OZ SLEEK | F5: Can Raw Materials | G5: Accounts Payable (A/P) | H5: 6314.88
A6: 08/19/2024 | B6: Bill | C6: DC11519 | D6: DigiCan Printing LLC | E6: CAN OAKTOWN ROOT BEER 12OZ SLEEK EMPTY | F6: Can Raw Materials | G6: Accounts Payable (A/P) | H6: 6314.88
A7: 08/19/2024 | B7: Bill | C7: DC11519 | D7: DigiCan Printing LLC | E7: CAN OLD FOUNTAIN CREME 12OZ SLEEK EMPTY | F7: Can Raw Materials | G7: Accounts Payable (A/P) | H7: 6314.88
A8: 45614 | B8: Bill | C8: DC11519 | D8: DigiCan Printing LLC | E8: CAN OLD FOUNTAIN CREME 12OZ SLEEK EMPTY | F8: Can Raw Materials | G8: Accounts Payable (A/P) | H8: =I8*0.33*-1 -> -6660.72 | I8: ='Excess worksheet 11-26-2024'!I14*24 -> 20184 | J8: units leftover from production run
H9: =SUM(H2:H8) -> 24980.68
A11: 08/19/2024 | B11: Bill | C11: DC11519 | D11: DigiCan Printing LLC | E11: 202-LOE-BLK-12OZ SLEEK BLK CAN LIDS | F11: Can Raw Materials | G11: Accounts Payable (A/P) | H11: 6679.2
A12: 45614 | B12: Bill | C12: DC11519 | D12: DigiCan Printing LLC | E12: 202-LOE-BLK-12OZ SLEEK BLK CAN LIDS | F12: Can Raw Materials | G12: Accounts Payable (A/P) | H12: =I12*0.07*-1 -> -353.22 | I12: 5046 | J12: units leftover from production run
H13: =SUM(H11:H12) -> 6325.98
A15: 10/15/2024 | B15: Bill | C15: 26331 | D15: AC CALDERONI* | E15: ONE GALLON NATURAL SYRUP HANGAR 25 COLA FOR CANS | F15: Can Raw Materials | G15: Accounts Payable (A/P) | H15: 2620.8 | J15: =390 -> 390 | K15: =J15*128 -> 49920 | L15: =K15*6 -> 299520 | M15: =L15/12 -> 24960 | N15: =M15/24 -> 1040 | O15: =H15/M15 -> 0.105
A16: 10/15/2024 | B16: Bill | C16: 26331 | D16: AC CALDERONI* | E16: ONE GALLON NATURAL SYRUP CABLE CAR LEMON LIME FOR CANS | F16: Can Raw Materials | G16: Accounts Payable (A/P) | H16: 2706.6
A17: 10/15/2024 | B17: Bill | C17: 26331 | D17: AC CALDERONI* | E17: ONE GALLON NATURAL SYRUP OAKTOWN OLD FASHIONED ROOT BEER FOR CANS | F17: Can Raw Materials | G17: Accounts Payable (A/P) | H17: 2730
A18: 10/15/2024 | B18: Bill | C18: 26331 | D18: AC CALDERONI* | E18: ONE GALLON NATURAL SYRUP OLDE FOUNTAIN CRÈME FOR CANS | F18: Can Raw Materials | G18: Accounts Payable (A/P) | H18: 2901.6 | M18: units
A19: 10/15/2024 | B19: Bill | C19: 26331 | D19: AC CALDERONI* | E19: ONE GALLON NATURAL SYRUP GOLDEN GATE ORANGE FOR CANS | F19: Can Raw Materials | G19: Accounts Payable (A/P) | H19: 2901.6 | J19: 390 | K19: =J19*128 -> 49920 | L19: =K19*6 -> 299520 | M19: =L19/12 -> 24960 | N19: =M19/24 -> 1040 | O19: =H19/M22 -> 0.02325
M20: =M19*5 -> 124800
A21: 45614 | B21: Bill | C21: 26331 | D21: AC CALDERONI* | E21: ONE GALLON NATURAL SYRUP GOLDEN GATE ORANGE FOR CANS | F21: Can Raw Materials | G21: Accounts Payable (A/P) | H21: ='Excess worksheet 11-26-2024'!N34*-1 -> -3116.5575 | I21: ='Excess worksheet 11-26-2024'!L34 -> 438.9375 | M21: =M19*0.05 -> 1248
H22: =SUM(H15:H19) -> 13860.6 | J22: =390*5 -> 1950 | K22: =J22*128 -> 249600 | L22: =K22*6 -> 1497600 | M22: =L22/12 -> 124800 | N22: =M22/24 -> 5200 | O22: =H22/M22 -> 0.1110625
A24: 10/25/2024 | B24: Bill | C24: 120675481 | D24: TFC LLC | E24: Invoice for transportation services from TFC LLC to Brix Beverage for linehaul delivery of can ends | F24: Can Raw Materials | G24: Accounts Payable (A/P) | H24: 2775
A25: 11/05/2024 | B25: Bill | C25: 120830631 | D25: TFC LLC | F25: Can Raw Materials | G25: Accounts Payable (A/P) | H25: 276
A26: 11/23/2024 | B26: Bill | C26: 120883663 | D26: TFC LLC | F26: Can Raw Materials | G26: Accounts Payable (A/P) | H26: 1995 | K26: =J19*5 -> 1950
A27: 11/23/2024 | B27: Bill | C27: 120883663 | D27: TFC LLC | F27: Can Raw Materials | G27: Accounts Payable (A/P) | H27: 1995 | K27: =K26*128*6 -> 1497600
A28: 10/15/2024 | B28: Bill | C28: 26331 | D28: AC CALDERONI* | E28: Freight to Full Metal | F28: Can Raw Materials | G28: Accounts Payable (A/P) | K28: =K27/12 -> 124800
H29: =SUM(H24:H28) -> 7041 | K29: =K28/24 -> 5200
A31: 11/05/2024 | B31: Expense | C31: INV42464 | D31: Can Source | E31: Packaging for Cases | F31: Can Raw Materials | G31: Chase Business Checking | H31: 1811
A33: 11/14/2024 | B33: Bill | C33: INVFMC80 | D33: Full Metal Canning | E33: Full Metal Canning | F33: Can Raw Materials | G33: Accounts Payable (A/P) | I33: Not paying this shit
G35: QUANTUM FILL | I35: =280*6 -> 1680
G37: Total Production Run | H37: =H33+H31+H29+H22+H13+H9 -> 54019.26
A40: 10/23/2024 | B40: Bill | C40: 24-164 | D40: Mark Caporale | E40: Invoice for consulting services - Process Authority Letters for Alameda Soda Company | F40: Can Raw Materials | G40: Accounts Payable (A/P) | H40: 4200 | I40: *Not included in COGS
F43: *Add Quantum bill | G43: 45614 | I43: DIF | J43: ='05-10-2024 Production Run'!G44 -> 45422 | L43: DIF | M43: 45314 | Q43: 3rd delivery - Added 12/31/2024
F44: *Need to add those pallets that just arrived | G44: Finished Cans | H44: =(4029.5*24)+R50 -> 101268 | J44: ='05-10-2024 Production Run'!G45 -> Finished Cans | K44: ='05-10-2024 Production Run'!H45 -> 158683 | M44: ='01-23-204 Production Run'!H30 -> Finished Cans | N44: ='01-23-204 Production Run'!I30 -> 65904 | Q44: Orange | R44: 70 | S44: =R44*24 -> 1680
M45: ='01-23-204 Production Run'!H31 -> 0 | N45: ='01-23-204 Production Run'!I31 -> 0 | Q45: cola | R45: 36 | S45: =R45*24 -> 864
H46: Cost Per Can | K46: ='05-10-2024 Production Run'!H47 -> Cost Per Can | M46: ='01-23-204 Production Run'!H32 -> 0 | N46: ='01-23-204 Production Run'!I32 -> Cost Per Can | Q46: Lemon Lime | R46: 24 | S46: =R46*24 -> 576
F47: =$H$44*I47 -> -2305.8969 | G47: Cans | H47: =H9/H44 -> 0.24667891 | I47: =H47-K47 -> -0.022770242 | J47: ='05-10-2024 Production Run'!G48 -> Cans | K47: ='05-10-2024 Production Run'!H48 -> 0.26944915 | L47: =K47-N47 -> -0.010838841 | M47: ='01-23-204 Production Run'!H33 -> Cans | N47: ='01-23-204 Production Run'!I33 -> 0.28028799 | Q47: Cream Soda | R47: 24 | S47: =R47*24 -> 576
F48: =$H$44*I48 -> 900.37055 | G48: Lids | H48: =H11/H44 -> 0.065955682 | I48: =H48-K48 -> 0.008890968 | J48: ='05-10-2024 Production Run'!G49 -> Lids | K48: ='05-10-2024 Production Run'!H49 -> 0.057064714 | L48: =K48-N48 -> 0.057064714 | M48: ='01-23-204 Production Run'!H34 -> Lids | N48: ='01-23-204 Production Run'!I34 -> 0 | Q48: Root Beer | R48: 36 | S48: =R48*24 -> 864
C49: This is our savings at FM's fill rate of .39 | D49: =H33-F49 -> 39800.335 | E49: This is our savings with the discount | F49: =$H$44*I49 -> -39800.335 | G49: Fill | H49: 0 | I49: =H49-K49 -> -0.39301986 | J49: ='05-10-2024 Production Run'!G50 -> Fill | K49: ='05-10-2024 Production Run'!H50 -> 0.39301986 | L49: =K49-N49 -> -0.0091281156 | M49: ='01-23-204 Production Run'!H35 -> Fill | N49: ='01-23-204 Production Run'!I35 -> 0.40214797 | R49: =SUM(R44:R48) -> 190 | S49: =SUM(S44:S48) -> 4560
F50: =$H$44*I50 -> 4367.1278 | G50: Raw Ingredients | H50: =H22/H44 -> 0.13687048 | I50: =H50-K50 -> 0.04312446 | J50: ='05-10-2024 Production Run'!G51 -> Raw Ingredients | K50: ='05-10-2024 Production Run'!H51 -> 0.093746022 | L50: =K50-N50 -> -0.091600846 | M50: ='01-23-204 Production Run'!H36 -> Raw Ingredients | N50: ='01-23-204 Production Run'!I36 -> 0.18534687 | Q50: Units | R50: =R49*24 -> 4560
E51: Higher because we didn’t get a full yield (until Quantum run) | F51: =$H$44*I51 -> -1944.5463 | G51: Shipping | H51: =H29/H44 -> 0.06952838 | I51: =H51-K51 -> -0.019201982 | J51: ='05-10-2024 Production Run'!G52 -> Shipping | K51: ='05-10-2024 Production Run'!H52 -> 0.088730362 | L51: =K51-N51 -> 0.049279039 | M51: ='01-23-204 Production Run'!H37 -> Shipping | N51: ='01-23-204 Production Run'!I37 -> 0.039451323
...

Sheet Excess worksheet 11-26-2024
E5: *1900 gallon tank, 90-95% yield goal
B6: CANS
B7: 45622 | L7: 6 to a case?
C8: Sent | D8: 100% Yield | E8: 95% Yield | F8: Filled | G8: Shipped | H8: To be Shipped | I8: Empties | J8: Cans | L8: Lids
A9: =F9/C9 -> 0.79150198 | B9: Cola | C9: =24288/24 -> 1012 | D9: 844 | E9: =D9*0.95 -> 801.8 | F9: 801 | G9: =8*96 -> 768 | H9: =F9-G9 -> 33 | I9: =(24288/24)-H9-F9 -> 178 | J9: 0.33 | L9: 0.07
B10: RB | C10: =24288/24 -> 1012 | D10: 844 | E10: =D10*0.95 -> 801.8 | F10: 807 | G10: =8*96 -> 768 | H10: =F10-G10 -> 39 | I10: =(24288/24)-H10-F10 -> 166 | J10: 0.33 | L10: 0.07
B11: LL | C11: =24288/24 -> 1012 | D11: 844 | E11: =D11*0.95 -> 801.8 | F11: 792 | G11: =8*96 -> 768 | H11: =F11-G11 -> 24 | I11: =(24288/24)-H11-F11 -> 196 | J11: 0.33 | L11: 0.07
B12: Orange | C12: =24288/24 -> 1012 | D12: 844 | E12: =D12*0.95 -> 801.8 | F12: 837 | G12: =8*96 -> 768 | H12: =F12-G12 -> 69 | I12: =(24288/24)-H12-F12 -> 106 | J12: 0.33 | L12: 0.07
B13: Crème | C13: =24288/24 -> 1012 | D13: 844 | E13: =D13*0.95 -> 801.8 | F13: 792.5 | G13: =8*96 -> 768 | H13: =F13-G13 -> 24.5 | I13: =(24288/24)-H13-F13 -> 195 | J13: 0.33 | L13: 0.07
B14: Total | C14: =SUM(C9:C13) -> 5060 | D14: =SUM(D9:D13) -> 4220 | E14: =SUM(E9:E13) -> 4009 | F14: =SUM(F9:F13) -> 4029.5 | G14: =SUM(G9:G13) -> 3840 | H14: =SUM(H9:H13) -> 189.5 | I14: =SUM(I9:I13) -> 841 | J14: 0.33 | K14: =I14*24*J14 -> 6660.72 | L14: 0.07 | M14: =I14*6*L14 -> 353.22 | N14: =(I14*J14*24)+(I14*L14*24) -> 8073.6 | O14: This is value leftover of cans and lids
B15: Pallets | C15: =C14/96 -> 52.708333 | D15: =D14/96 -> 43.958333 | E15: =E14/96 -> 41.760417 | F15: =F14/96 -> 41.973958 | G15: =G14/96 -> 40 | H15: =H14/96 -> 1.9739583 | I15: =I14/96 -> 8.7604167
N16: 83825.24 | O16: Total Production Cost
B17: *Revised proposed run by FMC 08/23/2024, adjusted | N17: =N14 -> 8073.6 | O17: This is value leftover of cans and lids
B18: to reflect our 1900g tank | N18: =N16-N17 -> 75751.64 | O18: adjusted production cogs
B19: 6 skus | C19: Gallons | D19: Cases | E19: Cans
B20: Cola | C20: 1900 | D20: 844 | E20: 20256
B21: Lemon Lime | C21: 1900 | D21: 844 | E21: 20256
B22: Rootbeer | C22: 1900 | D22: 844 | E22: 20256
B23: Ginger Beer | C23: 1500 | D23: 666 | E23: 15984
B24: Orange | C24: 1500 | D24: 666 | E24: 15984
B25: Crème | C25: 1500 | D25: 666 | E25: 15984
B28: Syrup | C28: Filled Cases | D28: Cans | E28: Ounces | F28: Gallons | G28: Gallons Sent | H28: Ounces Sent | I28: 5/1 Ratio | J28: Finished Gallons Sent | K28: Excess | L28: Concentrate Excess | M28: COGS per gallon | N28: Value of excess syrup at Full Metal
B29: Cola | C29: 801 | D29: =C29*24 -> 19224 | E29: =D29*12 -> 230688 | F29: =E29/128 -> 1802.25 | G29: 390 | H29: =G29*128 -> 49920 | I29: =H29*6 -> 299520 | J29: =I29/128 -> 2340 | K29: =J29-F29 -> 537.75 | L29: =K29/6 -> 89.625 | M29: 6.72 | N29: =L29*M29 -> 602.28
B30: RB | C30: 807 | D30: =C30*24 -> 19368 | E30: =D30*12 -> 232416 | F30: =E30/128 -> 1815.75 | G30: 390 | H30: =G30*128 -> 49920 | I30: =H30*6 -> 299520 | J30: =I30/128 -> 2340 | K30: =J30-F30 -> 524.25 | L30: =K30/6 -> 87.375 | M30: 6.94 | N30: =L30*M30 -> 606.3825
B31: LL | C31: 792 | D31: =C31*24 -> 19008 | E31: =D31*12 -> 228096 | F31: =E31/128 -> 1782 | G31: 390 | H31: =G31*128 -> 49920 | I31: =H31*6 -> 299520 | J31: =I31/128 -> 2340 | K31: =J31-F31 -> 558 | L31: =K31/6 -> 93 | M31: 7 | N31: =L31*M31 -> 651
B32: Orange | C32: 837 | D32: =C32*24 -> 20088 | E32: =D32*12 -> 241056 | F32: =E32/128 -> 1883.25 | G32: 390 | H32: =G32*128 -> 49920 | I32: =H32*6 -> 299520 | J32: =I32/128 -> 2340 | K32: =J32-F32 -> 456.75 | L32: =K32/6 -> 76.125 | M32: 7.44 | N32: =L32*M32 -> 566.37
B33: Crème | C33: 792.5 | D33: =C33*24 -> 19020 | E33: =D33*12 -> 228240 | F33: =E33/128 -> 1783.125 | G33: 390 | H33: =G33*128 -> 49920 | I33: =H33*6 -> 299520 | J33: =I33/128 -> 2340 | K33: =J33-F33 -> 556.875 | L33: =K33/6 -> 92.8125 | M33: 7.44 | N33: =L33*M33 -> 690.525
L34: =SUM(L29:L33) -> 438.9375 | N34: =SUM(N29:N33) -> 3116.5575

Sheet 05-10-2024 Production Run
A1: Date | B1: Transaction Type | C1: Num | D1: Name | E1: Memo/Description | F1: Account | G1: Split | H1: Amount
A3: 04/11/2024 | B3: Bill | C3: 25911 | D3: AC CALDERONI* | E3: ONE GALLON NATURAL SYRUP DIET HANGAR 25 COLA FOR CANS | F3: Can Raw Materials | G3: Accounts Payable (A/P) | H3: 1742.5
A4: 04/11/2024 | B4: Bill | C4: 25911 | D4: AC CALDERONI* | E4: ONE GALLON NATURAL SYRUP CABLE CAR LEMON LIME FOR CANS | F4: Can Raw Materials | G4: Accounts Payable (A/P) | H4: 2151.4
A5: 04/11/2024 | B5: Bill | C5: 25911 | D5: AC CALDERONI* | E5: ONE GALLON NATURAL SYRUP GOLDEN GATE ORANGE FOR CANS | F5: Can Raw Materials | G5: Accounts Payable (A/P) | H5: 2306.4
A6: 04/11/2024 | B6: Bill | C6: 25911 | D6: AC CALDERONI* | E6: ONE GALLON NATURAL SYRUP HANGAR 25 COLA FOR CANS | F6: Can Raw Materials | G6: Accounts Payable (A/P) | H6: 2755.2
A7: 04/11/2024 | B7: Bill | C7: 25911 | D7: AC CALDERONI* | E7: ONE GALLON NATURAL SYRUP OAKTOWN OLD FASHIONED ROOT BEER FOR CANS | F7: Can Raw Materials | G7: Accounts Payable (A/P) | H7: 2870
A8: 04/11/2024 | B8: Bill | C8: 25911 | D8: AC CALDERONI* | E8: ONE GALLON NATURAL SYRUP OLDE FOUNTAIN CRÈME FOR CANS | F8: Can Raw Materials | G8: Accounts Payable (A/P) | H8: 3050.4
H9: =SUM(H3:H8) -> 14875.9
A12: 04/17/2024 | B12: Bill | C12: 11703 | D12: DigiCan Printing LLC | E12: CAN CABLE CAR 12OZ SLEEK EMPTY | F12: Can Raw Materials | G12: Accounts Payable (A/P) | H12: 5130.84
A13: 04/17/2024 | B13: Bill | C13: 11703 | D13: DigiCan Printing LLC | E13: CAN GOLDEN GATE ORANGE 12OZ SLEEK | F13: Can Raw Materials | G13: Accounts Payable (A/P) | H13: 5130.84
A14: 04/17/2024 | B14: Bill | C14: 11703 | D14: DigiCan Printing LLC | E14: CAN LOST ISLAND GINGER 12OZ SLEEK EMPTY | F14: Can Raw Materials | G14: Accounts Payable (A/P) | H14: 5130.84
A15: 04/17/2024 | B15: Bill | C15: 11703 | D15: DigiCan Printing LLC | E15: CAN HANGAR 25 COLA 12OZ SLEEK | F15: Can Raw Materials | G15: Accounts Payable (A/P) | H15: 6841.12
A16: 04/17/2024 | B16: Bill | C16: 11703 | D16: DigiCan Printing LLC | E16: CAN HANGAR 25 DIET COLA 12OZ SLEEK EMPTY | F16: Can Raw Materials | G16: Accounts Payable (A/P) | H16: 6841.12
A17: 04/17/2024 | B17: Bill | C17: 11703 | D17: DigiCan Printing LLC | E17: CAN OAKTOWN ROOT BEER 12OZ SLEEK EMPTY | F17: Can Raw Materials | G17: Accounts Payable (A/P) | H17: 6841.12
A18: 04/17/2024 | B18: Bill | C18: 11703 | D18: DigiCan Printing LLC | E18: CAN OLD FOUNTAIN CREME 12OZ SLEEK EMPTY | F18: Can Raw Materials | G18: Accounts Payable (A/P) | H18: 6841.12
H19: =SUM(H12:H18) -> 42757
A21: 04/17/2024 | B21: Bill | C21: 11703 | D21: DigiCan Printing LLC | E21: 202-LOE-BLK-12OZ SLEEK BLK CAN LIDS | F21: Can Raw Materials | G21: Accounts Payable (A/P) | H21: 9055.2
